Workbook

Sheet Read me
A1: World Bank income classification, 1987 to 2050
A3: © Philip Schellekens | Moving Frontiers | movingfrontiers.substack.com
A5: YELLOW cells are projection. Unshaded cells are actual observed data.
A7: THE SIX ASSUMPTIONS
A8: Each one sits in a labelled cell on the Assumptions sheet and drives the projection through
A9: formulas. Change a cell and everything downstream re-computes.
A11: 1. Starting level. Each economy starts from its latest reported GNI per capita, Atlas method,
A12: used exactly as published. No value is adjusted to fit the band implied by its 2025 class.
A14: 2. Growth rate. The median of the ten annual growth rates over the decade to 2025, that is the
A15: changes 2015-16 through 2024-25. A median rather than a compound rate, so that a single
A16: devaluation year or one-off spike cannot set a twenty-five year path.
A18: 3. Threshold drift. One common rate of 1.244 percent a year for all three thresholds. The Bank
... A62: levels charts and play no part in the classification projection itself.

Sheet Coverage
A1: How many economies the projection covers, and where the others drop out
A2: An annual rate for year y needs a GNI per capita value in both y-1 and y. The decade to 2025 therefore holds ten rates, 2015-16 through 2024-25, which require eleven consecutive annual values from 2015 to 2025.
A4: Step | B4: Economies | C4: Set aside here | D4: 2050 population, millions | E4: Share of the 2050 total
A5: Listed on the OGHIST Country Analytical History worksheet | B5: 226
A6: Parsed into this workbook | B6: 224 | C6: 2
A7: Classified in at least one year, 1987 to 2025 | B7: 224 | C7: 0
A8: Classified in 2025, the base for the projection | B8: 218 | C8: 6 | D8: 9481.4 | E8: 1
A9: of which projected forward: 8 or more of the 10 annual rates | B9: 197 | D9: 9277.4 | E9: 0.97847889
A10: of which held at their 2025 class for want of data | B10: 21 | D10: 204.1 | E10: 0.021521109
A11: The last two rows are a split of the 218, not a further loss. The 21 frozen economies stay in every chart and in every population total; their class is simply held at its 2025 value instead of being projected.
A13: Left the classification before 2025 (6)
A14: Czechoslovakia (former) | B14: last classified 1991
A15: Mayotte | B15: last classified 2010
A16: Netherlands Antilles (former) | B16: last classified 2009
A17: Serbia and Montenegro (former) | B17: last classified 2005
A18: USSR (former) | B18: last classified 1990
A19: Yugoslavia (former) | B19: last classified 1991
A21: Held at their 2025 class (21), with 2050 population
A22: Yemen, Rep. | B22: L | C22: 3 | D22: 59
A23: Korea, Dem. Rep. | B23: L | C23: 0 | D23: 43.5
A24: Syrian Arab Republic | B24: L | C24: 7 | D24: 38.2
A25: Taiwan, China | B25: H | C25: 0 | D25: 23.9
A26: South Sudan | B26: L | C26: 0 | D26: 19.4
A27: Cuba | B27: UM | C27: 4 | D27: 11.1
A28: Eritrea | B28: L | C28: 0 | D28: 7.8
A29: New Caledonia | B29: H | C29: 5 | D29: 0.3
A30: Channel Islands | B30: H | C30: 0 | D30: 0.2
A31: Guam | B31: H | C31: 0 | D31: 0.2
A32: Virgin Islands (U.S.) | B32: H | C32: 0 | D32: 0.1
A33: Andorra | B33: H | C33: 6 | D33: 0.1
... A42: St. Martin (French part) | B42: H | C42: 0 | D42: 0
A44: The 21 frozen economies carry 204 million people in 2050, 2.2 percent of the classified total. Fifteen are high-income territories of negligible size; the six that matter are Yemen, Korea Dem. Rep., Syria, South Sudan, Cuba and Eritrea.

Sheet Assumptions
A1: Assumptions
A2: Every projected figure in this workbook derives from these cells.
A4: Threshold drift, common to all three thresholds | C4: 0.01244 | D4: median annual increase over the decade to 2025
A5: Growth floor (set equal to the drift, so no economy is downgraded) | C5: =C4 -> 0.01244
A7: Growth cap, 90th percentile of decade medians within each group
B8: Low income | C8: 0.055948
B9: Lower-middle | C9: 0.074681
B10: Upper-middle | C10: 0.090712
B11: High income | C11: 0.071689
A13: Minimum observations required to project (of 10 possible) | C13: 8
A15: Derivation of the drift: annual change in each official threshold
A16: Year | B16: LIC / LMIC | C16: LMIC / UMIC | D16: UMIC / HIC
A17: 2016 | B17: -0.019512195 | C17: -0.019826518 | D17: -0.019238477
A18: 2017 | B18: -0.0099502488 | C18: -0.01517067 | D18: -0.014711892
A19: 2018 | B19: 0.030150754 | C19: 0.025673941 | D19: 0.026545002
A20: 2019 | B20: 0.0097560976 | C20: 0.012515645 | D20: 0.012929293
A21: 2020 | B21: 0.0096618357 | C21: 0.012360939 | D21: 0.01276426
A22: 2021 | B22: 0.038277512 | C22: 0.039072039 | D22: 0.040173297
A23: 2022 | B23: 0.046082949 | C23: 0.049353702 | D23: 0.04846649
A24: 2023 | B24: 0.0088105727 | C24: 0.011198208 | D24: 0.011556519
A25: 2024 | B25: -0.0087336245 | C25: -0.0044296788 | D25: -0.0049982149
A26: 2025 | B26: 0.035242291 | C26: 0.031145717 | D26: 0.03157517
A27: median | B27: =MEDIAN(B17:B26) -> 0.0097089667 | C27: =MEDIAN(C17:C26) -> 0.012438292 | D27: =MEDIAN(D17:D26) -> 0.012846777
A28: median of the three | B28: =MEDIAN(B27:D27) -> 0.012438292 | D28: this is the 1.244% used above

Sheet Thresholds
A1: Income classification thresholds, GNI per capita (Atlas method, current US$)
A2: 1987 to 2025 are the official thresholds exactly as published. 2026 onward drift at the rate on the Assumptions sheet.
A4: Year | B4: Status | C4: LIC / LMIC | D4: LMIC / UMIC | E4: UMIC / HIC
A5: 1987 | B5: official | C5: 480 | D5: 1940 | E5: 6000
A6: 1988 | B6: official | C6: 545 | D6: 2200 | E6: 6000
A7: 1989 | B7: official | C7: 580 | D7: 2335 | E7: 6000
A8: 1990 | B8: official | C8: 610 | D8: 2465 | E8: 7620
A9: 1991 | B9: official | C9: 635 | D9: 2555 | E9: 7910
A10: 1992 | B10: official | C10: 675 | D10: 2695 | E10: 8355
A11: 1993 | B11: official | C11: 695 | D11: 2785 | E11: 8625
A12: 1994 | B12: official | C12: 725 | D12: 2895 | E12: 8955
A13: 1995 | B13: official | C13: 765 | D13: 3035 | E13: 9385
A14: 1996 | B14: official | C14: 785 | D14: 3115 | E14: 9645
A15: 1997 | B15: official | C15: 785 | D15: 3125 | E15: 9655
A16: 1998 | B16: official | C16: 760 | D16: 3030 | E16: 9360
... A43: 2025 | B43: official | C43: 1175 | D43: 4635 | E43: 14375
A44: 2026 | B44: projected | C44: =C43*(1+Assumptions!$C$4) -> 1189.617 | D44: =D43*(1+Assumptions!$C$4) -> 4692.6594 | E44: =E43*(1+Assumptions!$C$4) -> 14553.825
A45: 2027 | B45: projected | C45: =C44*(1+Assumptions!$C$4) -> 1204.4158 | D45: =D44*(1+Assumptions!$C$4) -> 4751.0361 | E45: =E44*(1+Assumptions!$C$4) -> 14734.875
A46: 2028 | B46: projected | C46: =C45*(1+Assumptions!$C$4) -> 1219.3988 | D46: =D45*(1+Assumptions!$C$4) -> 4810.139 | E46: =E45*(1+Assumptions!$C$4) -> 14918.176
A47: 2029 | B47: projected | C47: =C46*(1+Assumptions!$C$4) -> 1234.5681 | D47: =D46*(1+Assumptions!$C$4) -> 4869.9771 | E47: =E46*(1+Assumptions!$C$4) -> 15103.759
A48: 2030 | B48: projected | C48: =C47*(1+Assumptions!$C$4) -> 1249.9261 | D48: =D47*(1+Assumptions!$C$4) -> 4930.5596 | E48: =E47*(1+Assumptions!$C$4) -> 15291.649
A49: 2031 | B49: projected | C49: =C48*(1+Assumptions!$C$4) -> 1265.4752 | D49: =D48*(1+Assumptions!$C$4) -> 4991.8958 | E49: =E48*(1+Assumptions!$C$4) -> 15481.877
A50: 2032 | B50: projected | C50: =C49*(1+Assumptions!$C$4) -> 1281.2177 | D50: =D49*(1+Assumptions!$C$4) -> 5053.995 | E50: =E49*(1+Assumptions!$C$4) -> 15674.472
A51: 2033 | B51: projected | C51: =C50*(1+Assumptions!$C$4) -> 1297.1561 | D51: =D50*(1+Assumptions!$C$4) -> 5116.8667 | E51: =E50*(1+Assumptions!$C$4) -> 15869.462
A52: 2034 | B52: projected | C52: =C51*(1+Assumptions!$C$4) -> 1313.2927 | D52: =D51*(1+Assumptions!$C$4) -> 5180.5205 | E52: =E51*(1+Assumptions!$C$4) -> 16066.879
A53: 2035 | B53: projected | C53: =C52*(1+Assumptions!$C$4) -> 1329.63 | D53: =D52*(1+Assumptions!$C$4) -> 5244.9662 | E53: =E52*(1+Assumptions!$C$4) -> 16266.75
A54: 2036 | B54: projected | C54: =C53*(1+Assumptions!$C$4) -> 1346.1706 | D54: =D53*(1+Assumptions!$C$4) -> 5310.2135 | E54: =E53*(1+Assumptions!$C$4) -> 16469.109
A55: 2037 | B55: projected | C55: =C54*(1+Assumptions!$C$4) -> 1362.917 | D55: =D54*(1+Assumptions!$C$4) -> 5376.2726 | E55: =E54*(1+Assumptions!$C$4) -> 16673.985
... A68: 2050 | B68: projected | C68: =C67*(1+Assumptions!$C$4) -> 1600.5537 | D68: =D67*(1+Assumptions!$C$4) -> 6313.6735 | E68: =E67*(1+Assumptions!$C$4) -> 19581.242

Sheet GNI per capita
A1: GNI per capita, Atlas method, current US$ - actual 1987-2025, projected 2026-2050 (yellow)
A3: Economy | B3: Code | C3: 2025 class | D3: Growth rate | E3: Starting level | F3: Level year | G3: Status | H3: 1987 | I3: 1988 | J3: 1989 | K3: 1990 | L3: 1991 | M3: 1992 | N3: 1993 | O3: 1994 | P3: 1995 | Q3: 1996 | R3: 1997 | S3: 1998 | T3: 1999 | U3: 2000 | V3: 2001 | W3: 2002 | X3: 2003 | Y3: 2004 | Z3: 2005 | AA3: 2006 | AB3: 2007 | AC3: 2008 | AD3: 2009 | AE3: 2010 | AF3: 2011 | AG3: 2012 | AH3: 2013 | AI3: 2014 | AJ3: 2015 | AK3: 2016 | AL3: 2017 | AM3: 2018 | AN3: 2019 | AO3: 2020 | AP3: 2021 | AQ3: 2022 | AR3: 2023 | AS3: 2024 | AT3: 2025 | AU3: 2026 | AV3: 2027 | AW3: 2028 | AX3: 2029 | AY3: 2030 | AZ3: 2031 | BA3: 2032 | BB3: 2033 | BC3: 2034 | BD3: 2035 | BE3: 2036 | BF3: 2037 | BG3: 2038 | BH3: 2039 | BI3: 2040 | BJ3: 2041 | BK3: 2042 | BL3: 2043 | BM3: 2044 | BN3: 2045 | BO3: 2046 | BP3: 2047 | BQ3: 2048 | BR3: 2049 | BS3: 2050
A4: Afghanistan | B4: AFG | C4: L | D4: ='Growth calculation'!G5 -> 0.01244 | E4: 390 | F4: 2024 | G4: projected - raised from -2.6% to the 1.244% floor | W4: 180 | X4: 190 | Y4: 210 | Z4: 250 | AA4: 270 | AB4: 330 | AC4: 370 | AD4: 460 | AE4: 530 | AF4: 550 | AG4: 640 | AH4: 670 | AI4: 640 | AJ4: 590 | AK4: 560 | AL4: 530 | AM4: 520 | AN4: 520 | AO4: 490 | AP4: 380 | AQ4: 370 | AR4: 370 | AS4: 390 | AU4: =$E4*(1+$D4) -> 394.8516 | AV4: =AU4*(1+$D4) -> 399.76355 | AW4: =AV4*(1+$D4) -> 404.73661 | AX4: =AW4*(1+$D4) -> 409.77154 | AY4: =AX4*(1+$D4) -> 414.86909 | AZ4: =AY4*(1+$D4) -> 420.03007 | BA4: =AZ4*(1+$D4) -> 425.25524 | BB4: =BA4*(1+$D4) -> 430.54541 | BC4: =BB4*(1+$D4) -> 435.9014 | ... BS4: =BR4*(1+$D4) -> 531.24761
A5: Albania | B5: ALB | C5: UM | D5: ='Growth calculation'!G6 -> 0.090712 | E5: 12060 | F5: 2025 | G5: projected - cut from 12.2% to the UM p90 cap of 9.07% | H5: 730 | I5: 730 | J5: 760 | K5: 650 | L5: 410 | M5: 280 | N5: 320 | O5: 380 | P5: 670 | Q5: 940 | R5: 860 | S5: 870 | T5: 960 | U5: 1130 | V5: 1320 | W5: 1420 | X5: 1700 | Y5: 2170 | Z5: 2690 | AA5: 3130 | AB5: 3580 | AC5: 4160 | AD5: 4390 | AE5: 4430 | AF5: 4460 | AG5: 4430 | AH5: 4690 | AI5: 4750 | AJ5: 4660 | AK5: 4670 | AL5: 4700 | AM5: 5400 | AN5: 5900 | AO5: 5970 | AP5: 6940 | AQ5: 7720 | AR5: 8740 | AS5: 9910 | AT5: 12060 | AU5: =$E5*(1+$D5) -> 13153.987 | AV5: =AU5*(1+$D5) -> 14347.211 | AW5: =AV5*(1+$D5) -> 15648.675 | AX5: =AW5*(1+$D5) -> 17068.198 | AY5: =AX5*(1+$D5) -> 18616.488 | AZ5: =AY5*(1+$D5) -> 20305.227 | BA5: =AZ5*(1+$D5) -> 22147.155 | BB5: =BA5*(1+$D5) -> 24156.168 | BC5: =BB5*(1+$D5) -> 26347.422 | ... BS5: =BR5*(1+$D5) -> 105705.99
A6: Algeria | B6: DZA | C6: UM | D6: ='Growth calculation'!G7 -> 0.015808597 | E6: 5850 | F6: 2025 | G6: projected | H6: 2850 | I6: 2780 | J6: 2590 | K6: 2400 | L6: 2010 | M6: 1930 | N6: 1750 | O6: 1640 | P6: 1570 | Q6: 1530 | R6: 1510 | S6: 1550 | T6: 1540 | U6: 1600 | V6: 1720 | W6: 1840 | X6: 2090 | Y6: 2440 | Z6: 2910 | AA6: 3310 | AB6: 3780 | AC6: 4430 | AD6: 4570 | AE6: 4870 | AF6: 5050 | AG6: 5630 | AH6: 5970 | AI6: 6030 | AJ6: 5390 | AK6: 4920 | AL6: 4440 | AM6: 4450 | AN6: 4480 | AO6: 4020 | AP6: 4120 | AQ6: 4430 | AR6: 4950 | AS6: 5370 | AT6: 5850 | AU6: =$E6*(1+$D6) -> 5942.4803 | AV6: =AU6*(1+$D6) -> 6036.4226 | AW6: =AV6*(1+$D6) -> 6131.8499 | AX6: =AW6*(1+$D6) -> 6228.7859 | AY6: =AX6*(1+$D6) -> 6327.2543 | AZ6: =AY6*(1+$D6) -> 6427.2793 | BA6: =AZ6*(1+$D6) -> 6528.8856 | BB6: =BA6*(1+$D6) -> 6632.0981 | BC6: =BB6*(1+$D6) -> 6736.9422 | ... BS6: =BR6*(1+$D6) -> 8658.7056
A7: American Samoa | B7: ASM | C7: H | G7: frozen - only 0 of 10 annual rates
A8: Andorra | B8: AND | C8: H | G8: frozen - only 6 of 10 annual rates | AN8: 46450 | AO8: 42450 | AP8: 44720 | AQ8: 47600 | AR8: 47920 | AS8: 47740 | AT8: 53230
A9: Angola | B9: AGO | C9: LM | D9: ='Growth calculation'!G10 -> 0.01244 | E9: 2860 | F9: 2025 | G9: projected - raised from -0.8% to the 1.244% floor | H9: 680 | I9: 660 | J9: 870 | K9: 790 | L9: 920 | M9: 340 | N9: 290 | O9: 190 | P9: 370 | Q9: 370 | R9: 450 | S9: 420 | T9: 340 | U9: 360 | V9: 400 | W9: 620 | X9: 780 | Y9: 1190 | Z9: 1590 | AA9: 2090 | AB9: 2800 | AC9: 3450 | AD9: 3680 | AE9: 3780 | AF9: 3960 | AG9: 4750 | AH9: 5330 | AI9: 5430 | AJ9: 4450 | AK9: 2960 | AL9: 2440 | AM9: 2300 | AN9: 2460 | AO9: 2000 | AP9: 1960 | AQ9: 2290 | AR9: 2650 | AS9: 2850 | AT9: 2860 | AU9: =$E9*(1+$D9) -> 2895.5784 | AV9: =AU9*(1+$D9) -> 2931.5994 | AW9: =AV9*(1+$D9) -> 2968.0685 | AX9: =AW9*(1+$D9) -> 3004.9913 | AY9: =AX9*(1+$D9) -> 3042.3734 | AZ9: =AY9*(1+$D9) -> 3080.2205 | BA9: =AZ9*(1+$D9) -> 3118.5384 | BB9: =BA9*(1+$D9) -> 3157.333 | BC9: =BB9*(1+$D9) -> 3196.6103 | ... BS9: =BR9*(1+$D9) -> 3895.8158
A10: Antigua and Barbuda | B10: ATG | C10: H | D10: ='Growth calculation'!G11 -> 0.065642147 | E10: 23790 | F10: 2025 | G10: projected | H10: 4840 | I10: 6050 | J10: 6550 | K10: 7040 | L10: 7550 | M10: 7850 | N10: 8410 | O10: 9000 | P10: 8730 | Q10: 9380 | R10: 9850 | S10: 10130 | T10: 10590 | U10: 11200 | V10: 10610 | W10: 10710 | X10: 11680 | Y10: 12850 | Z10: 14050 | AA10: 15740 | AB10: 17310 | AC10: 17750 | AD10: 15750 | AE10: 14390 | AF10: 14100 | AG10: 14530 | AH10: 14500 | AI10: 14830 | AJ10: 14550 | AK10: 15080 | AL10: 15860 | AM10: 17460 | AN10: 18250 | AO10: 15460 | AP10: 16690 | AQ10: 18730 | AR10: 20250 | AS10: 21200 | AT10: 23790 | AU10: =$E10*(1+$D10) -> 25351.627 | AV10: =AU10*(1+$D10) -> 27015.762 | AW10: =AV10*(1+$D10) -> 28789.134 | AX10: =AW10*(1+$D10) -> 30678.915 | AY10: =AX10*(1+$D10) -> 32692.745 | AZ10: =AY10*(1+$D10) -> 34838.767 | BA10: =AZ10*(1+$D10) -> 37125.658 | BB10: =BA10*(1+$D10) -> 39562.666 | BC10: =BB10*(1+$D10) -> 42159.645 | ... BS10: =BR10*(1+$D10) -> 116594.79
A11: Argentina | B11: ARG | C11: UM | D11: ='Growth calculation'!G12 -> 0.06235372 | E11: 14650 | F11: 2025 | G11: projected | H11: 3490 | I11: 3860 | J11: 2910 | K11: 3180 | L11: 3850 | M11: 6040 | N11: 7080 | O11: 7570 | P11: 7310 | Q11: 7680 | R11: 8080 | S11: 7960 | T11: 7510 | U11: 7400 | V11: 6930 | W11: 4010 | X11: 3620 | Y11: 3340 | Z11: 4230 | AA11: 5440 | AB11: 6460 | AC11: 7600 | AD11: 7720 | AE11: 9160 | AF11: 10590 | AG11: 11770 | AH11: 12760 | AI11: 12240 | AJ11: 12500 | AK11: 12130 | AL11: 13070 | AM11: 12390 | AN11: 11210 | AO11: 9040 | AP11: 10070 | AQ11: 11890 | AR11: 12920 | AS11: 13530 | AT11: 14650 | AU11: =$E11*(1+$D11) -> 15563.482 | AV11: =AU11*(1+$D11) -> 16533.923 | AW11: =AV11*(1+$D11) -> 17564.875 | AX11: =AW11*(1+$D11) -> 18660.11 | AY11: =AX11*(1+$D11) -> 19823.637 | AZ11: =AY11*(1+$D11) -> 21059.715 | BA11: =AZ11*(1+$D11) -> 22372.866 | BB11: =BA11*(1+$D11) -> 23767.898 | BC11: =BB11*(1+$D11) -> 25249.914 | ... BS11: =BR11*(1+$D11) -> 66460.897
A12: Armenia | B12: ARM | C12: UM | D12: ='Growth calculation'!G13 -> 0.090712 | E12: 9020 | F12: 2025 | G12: projected - cut from 9.2% to the UM p90 cap of 9.07% | M12: 300 | N12: 350 | O12: 390 | P12: 460 | Q12: 500 | R12: 540 | S12: 570 | T12: 600 | U12: 630 | V12: 680 | W12: 760 | X12: 910 | Y12: 1120 | Z12: 1460 | AA12: 1910 | AB12: 2600 | AC12: 3390 | AD12: 3140 | AE12: 3280 | AF12: 3360 | AG12: 3700 | AH12: 3940 | AI12: 4000 | AJ12: 3910 | AK12: 3690 | AL12: 3900 | AM12: 4220 | AN12: 4650 | AO12: 4230 | AP12: 4580 | AQ12: 5690 | AR12: 6850 | AS12: 7810 | AT12: 9020 | AU12: =$E12*(1+$D12) -> 9838.2222 | AV12: =AU12*(1+$D12) -> 10730.667 | AW12: =AV12*(1+$D12) -> 11704.067 | AX12: =AW12*(1+$D12) -> 12765.767 | AY12: =AX12*(1+$D12) -> 13923.775 | AZ12: =AY12*(1+$D12) -> 15186.828 | BA12: =AZ12*(1+$D12) -> 16564.456 | BB12: =BA12*(1+$D12) -> 18067.051 | BC12: =BB12*(1+$D12) -> 19705.949 | ... BS12: =BR12*(1+$D12) -> 79060.366
A13: Aruba | B13: ABW | C13: H | D13: ='Growth calculation'!G14 -> 0.050729443 | E13: 35200 | F13: 2024 | G13: projected | I13: 10670 | J13: 11870 | K13: 12120 | L13: 12940 | M13: 13840 | N13: 14380 | O13: 15460 | P13: 16340 | Q13: 16410 | R13: 17050 | S13: 17390 | T13: 17750 | U13: 20060 | V13: 20340 | W13: 19220 | X13: 21020 | Y13: 23610 | Z13: 19720 | AA13: 23920 | AB13: 22600 | AC13: 26780 | AD13: 24340 | AE13: 23050 | AF13: 23100 | AG13: 23970 | AH13: 24830 | AI13: 25260 | AJ13: 25430 | AK13: 25560 | AL13: 26460 | AM13: 27970 | AN13: 29320 | AO13: 22750 | AP13: 26550 | AQ13: 30160 | AR13: 31690 | AS13: 35200 | AU13: =$E13*(1+$D13) -> 36985.676 | AV13: =AU13*(1+$D13) -> 38861.939 | AW13: =AV13*(1+$D13) -> 40833.384 | AX13: =AW13*(1+$D13) -> 42904.838 | AY13: =AX13*(1+$D13) -> 45081.377 | AZ13: =AY13*(1+$D13) -> 47368.33 | BA13: =AZ13*(1+$D13) -> 49771.299 | BB13: =BA13*(1+$D13) -> 52296.169 | BC13: =BB13*(1+$D13) -> 54949.125 | ... BS13: =BR13*(1+$D13) -> 121287.27
A14: Australia | B14: AUS | C14: H | D14: ='Growth calculation'!G15 -> 0.026767382 | E14: 64120 | F14: 2025 | G14: projected | H14: 12580 | I14: 14160 | J14: 15620 | K14: 17370 | L14: 18260 | M14: 18600 | N14: 18980 | O14: 18950 | P14: 19400 | Q14: 20620 | R14: 22090 | S14: 21960 | T14: 21650 | U14: 21340 | V14: 20370 | W14: 20240 | X14: 21420 | Y14: 25890 | Z14: 30790 | AA14: 34670 | AB14: 37470 | AC14: 42510 | AD14: 44230 | AE14: 46900 | AF14: 50570 | AG14: 60500 | AH14: 66360 | AI14: 65500 | AJ14: 60780 | AK14: 54330 | AL14: 51700 | AM14: 53280 | AN14: 55090 | AO14: 53770 | AP14: 57220 | AQ14: 60790 | AR14: 63320 | AS14: 62680 | AT14: 64120 | AU14: =$E14*(1+$D14) -> 65836.325 | AV14: =AU14*(1+$D14) -> 67598.591 | AW14: =AV14*(1+$D14) -> 69408.028 | AX14: =AW14*(1+$D14) -> 71265.899 | AY14: =AX14*(1+$D14) -> 73173.501 | AZ14: =AY14*(1+$D14) -> 75132.164 | BA14: =AZ14*(1+$D14) -> 77143.255 | BB14: =BA14*(1+$D14) -> 79208.178 | BC14: =BB14*(1+$D14) -> 81328.373 | ... BS14: =BR14*(1+$D14) -> 124106.66
A15: Austria | B15: AUT | C15: H | D15: ='Growth calculation'!G16 -> 0.018750628 | E15: 60360 | F15: 2025 | G15: projected | H15: 13760 | I15: 18000 | J15: 19220 | K15: 20550 | L15: 21720 | M15: 24430 | N15: 24770 | O15: 26040 | P15: 28080 | Q15: 29930 | R15: 29410 | S15: 27810 | T15: 26980 | U15: 26660 | V15: 25190 | W15: 24860 | X15: 27950 | Y15: 33610 | Z15: 38510 | AA15: 41170 | AB15: 44230 | AC15: 48890 | AD15: 48900 | AE15: 49460 | AF15: 50380 | AG15: 49760 | AH15: 50260 | AI15: 49960 | AJ15: 47190 | AK15: 45980 | AL15: 44800 | AM15: 48710 | AN15: 50900 | AO15: 49000 | AP15: 53440 | AQ15: 56310 | AR15: 55890 | AS15: 54760 | AT15: 60360 | AU15: =$E15*(1+$D15) -> 61491.788 | AV15: =AU15*(1+$D15) -> 62644.798 | AW15: =AV15*(1+$D15) -> 63819.427 | AX15: =AW15*(1+$D15) -> 65016.081 | AY15: =AX15*(1+$D15) -> 66235.174 | AZ15: =AY15*(1+$D15) -> 67477.125 | BA15: =AZ15*(1+$D15) -> 68742.363 | BB15: =BA15*(1+$D15) -> 70031.326 | BC15: =BB15*(1+$D15) -> 71344.457 | ... BS15: =BR15*(1+$D15) -> 96038.744
A16: Azerbaijan | B16: AZE | C16: UM | D16: ='Growth calculation'!G17 -> 0.049353469 | E16: 7360 | F16: 2025 | G16: projected | M16: 160 | N16: 110 | O16: 80 | P16: 180 | Q16: 240 | R16: 410 | S16: 510 | T16: 600 | U16: 630 | V16: 680 | W16: 740 | X16: 840 | Y16: 960 | Z16: 1290 | AA16: 1920 | AB16: 2740 | AC16: 3900 | AD16: 4820 | AE16: 5400 | AF16: 5490 | AG16: 6440 | AH16: 7450 | AI16: 7740 | AJ16: 6610 | AK16: 4790 | AL16: 4110 | AM16: 4080 | AN16: 4510 | AO16: 4480 | AP16: 4910 | AQ16: 5670 | AR16: 6680 | AS16: 7340 | AT16: 7360 | AU16: =$E16*(1+$D16) -> 7723.2415 | AV16: =AU16*(1+$D16) -> 8104.4103 | AW16: =AV16*(1+$D16) -> 8504.3911 | AX16: =AW16*(1+$D16) -> 8924.1123 | AY16: =AX16*(1+$D16) -> 9364.5482 | AZ16: =AY16*(1+$D16) -> 9826.7211 | BA16: =AZ16*(1+$D16) -> 10311.704 | BB16: =BA16*(1+$D16) -> 10820.622 | BC16: =BB16*(1+$D16) -> 11354.657 | ... BS16: =BR16*(1+$D16) -> 24542.731
A17: Bahamas, The | B17: BHS | C17: H | D17: ='Growth calculation'!G18 -> 0.041136431 | E17: 37020 | F17: 2024 | G17: projected | H17: 10030 | I17: 10880 | J17: 11540 | K17: 11020 | L17: 10530 | M17: 10750 | N17: 10530 | O17: 10790 | P17: 13250 | Q17: 14770 | R17: 13460 | S17: 16180 | T17: 22250 | U17: 23880 | V17: 24520 | W17: 25220 | X17: 25900 | Y17: 27470 | Z17: 28880 | AA17: 29230 | AB17: 29690 | AC17: 29660 | AD17: 27920 | AE17: 27320 | AF17: 26990 | AG17: 27910 | AH17: 26870 | AI17: 27220 | AJ17: 27620 | AK17: 27820 | AL17: 29570 | AM17: 30650 | AN17: 31630 | AO17: 25180 | AP17: 29910 | AQ17: 33790 | AR17: 35180 | AS17: 37020 | AU17: =$E17*(1+$D17) -> 38542.871 | AV17: =AU17*(1+$D17) -> 40128.387 | AW17: =AV17*(1+$D17) -> 41779.125 | AX17: =AW17*(1+$D17) -> 43497.77 | AY17: =AX17*(1+$D17) -> 45287.113 | AZ17: =AY17*(1+$D17) -> 47150.063 | BA17: =AZ17*(1+$D17) -> 49089.648 | BB17: =BA17*(1+$D17) -> 51109.021 | BC17: =BB17*(1+$D17) -> 53211.464 | ... BS17: =BR17*(1+$D17) -> 101420.91
A18: Bahrain | B18: BHR | C18: H | D18: ='Growth calculation'!G19 -> 0.01383147 | E18: 28790 | F18: 2025 | G18: projected | H18: 8630 | I18: 8730 | J18: 8530 | K18: 9880 | L18: 11240 | M18: 11380 | N18: 11590 | O18: 11180 | P18: 11920 | Q18: 12380 | R18: 11890 | S18: 11650 | T18: 11570 | U18: 12500 | V18: 12730 | W18: 12480 | X18: 13180 | Y18: 14680 | Z18: 16550 | AA18: 17850 | AB18: 19600 | AC18: 21070 | AD18: 18940 | AE18: 19510 | AF18: 20040 | AG18: 24670 | AH18: 25970 | AI18: 25480 | AJ18: 23640 | AK18: 22720 | AL18: 22360 | AM18: 24200 | AN18: 25800 | AO18: 23870 | AP18: 25240 | AQ18: 28300 | AR18: 28460 | AS18: 28170 | AT18: 28790 | AU18: =$E18*(1+$D18) -> 29188.208 | AV18: =AU18*(1+$D18) -> 29591.924 | AW18: =AV18*(1+$D18) -> 30001.224 | AX18: =AW18*(1+$D18) -> 30416.185 | AY18: =AX18*(1+$D18) -> 30836.885 | AZ18: =AY18*(1+$D18) -> 31263.405 | BA18: =AZ18*(1+$D18) -> 31695.824 | BB18: =BA18*(1+$D18) -> 32134.223 | BC18: =BB18*(1+$D18) -> 32578.687 | ... BS18: =BR18*(1+$D18) -> 40586.898
A19: Bangladesh | B19: BGD | C19: LM | D19: ='Growth calculation'!G20 -> 0.074681 | E19: 2840 | F19: 2025 | G19: projected - cut from 9.8% to the LM p90 cap of 7.47% | H19: 250 | I19: 270 | J19: 280 | K19: 290 | L19: 300 | M19: 300 | N19: 300 | O19: 300 | P19: 320 | Q19: 350 | R19: 370 | S19: 390 | T19: 400 | U19: 410 | V19: 420 | W19: 420 | X19: 440 | Y19: 490 | Z19: 530 | AA19: 550 | AB19: 580 | AC19: 640 | AD19: 700 | AE19: 780 | AF19: 870 | AG19: 950 | AH19: 1010 | AI19: 1080 | AJ19: 1200 | AK19: 1400 | AL19: 1640 | AM19: 2020 | AN19: 2220 | AO19: 2320 | AP19: 2600 | AQ19: 2850 | AR19: 2880 | AS19: 2820 | AT19: 2840 | AU19: =$E19*(1+$D19) -> 3052.094 | AV19: =AU19*(1+$D19) -> 3280.0275 | AW19: =AV19*(1+$D19) -> 3524.9832 | AX19: =AW19*(1+$D19) -> 3788.2325 | AY19: =AX19*(1+$D19) -> 4071.1415 | AZ19: =AY19*(1+$D19) -> 4375.1784 | BA19: =AZ19*(1+$D19) -> 4701.9211 | BB19: =BA19*(1+$D19) -> 5053.0652 | BC19: =BB19*(1+$D19) -> 5430.4332 | ... BS19: =BR19*(1+$D19) -> 17191.256
A20: Barbados | B20: BRB | C20: H | D20: ='Growth calculation'!G21 -> 0.026986562 | E20: 27080 | F20: 2025 | G20: projected | H20: 6710 | I20: 7460 | J20: 7920 | K20: 7670 | L20: 7640 | M20: 7540 | N20: 7770 | O20: 8110 | P20: 8470 | Q20: 8850 | R20: 9250 | S20: 9670 | T20: 10110 | U20: 11170 | V20: 11030 | W20: 11030 | X20: 11660 | Y20: 12660 | Z20: 13610 | AA20: 14630 | AB20: 15950 | AC20: 16600 | AD20: 16150 | AE20: 16220 | AF20: 17150 | AG20: 19080 | AH20: 19410 | AI20: 19620 | AJ20: 19280 | AK20: 19300 | AL20: 19570 | AM20: 20240 | AN20: 20800 | AO20: 18290 | AP20: 20700 | AQ20: 24760 | AR20: 24710 | AS20: 25360 | AT20: 27080 | AU20: =$E20*(1+$D20) -> 27810.796 | AV20: =AU20*(1+$D20) -> 28561.314 | AW20: =AV20*(1+$D20) -> 29332.086 | AX20: =AW20*(1+$D20) -> 30123.658 | AY20: =AX20*(1+$D20) -> 30936.592 | AZ20: =AY20*(1+$D20) -> 31771.464 | BA20: =AZ20*(1+$D20) -> 32628.866 | BB20: =BA20*(1+$D20) -> 33509.407 | BC20: =BB20*(1+$D20) -> 34413.711 | ... BS20: =BR20*(1+$D20) -> 52694.791
A21: Belarus | B21: BLR | C21: UM | D21: ='Growth calculation'!G22 -> 0.072291796 | E21: 9160 | F21: 2025 | G21: projected | M21: 1680 | N21: 1610 | O21: 1450 | P21: 1360 | Q21: 1440 | R21: 1520 | S21: 1540 | T21: 1410 | U21: 1380 | V21: 1300 | W21: 1380 | X21: 1630 | Y21: 2170 | Z21: 2820 | AA21: 3510 | AB21: 4310 | AC21: 5470 | AD21: 5660 | AE21: 6150 | AF21: 6350 | AG21: 6630 | AH21: 7030 | AI21: 7620 | AJ21: 6740 | AK21: 5640 | AL21: 5320 | AM21: 5730 | AN21: 6370 | AO21: 6410 | AP21: 7040 | AQ21: 7210 | AR21: 7850 | AS21: 8380 | AT21: 9160 | AU21: =$E21*(1+$D21) -> 9822.1929 | AV21: =AU21*(1+$D21) -> 10532.257 | AW21: =AV21*(1+$D21) -> 11293.653 | AX21: =AW21*(1+$D21) -> 12110.091 | AY21: =AX21*(1+$D21) -> 12985.551 | AZ21: =AY21*(1+$D21) -> 13924.3 | BA21: =AZ21*(1+$D21) -> 14930.913 | BB21: =BA21*(1+$D21) -> 16010.295 | BC21: =BB21*(1+$D21) -> 17167.708 | ... BS21: =BR21*(1+$D21) -> 52446.928
A22: Belgium | B22: BEL | C22: H | D22: ='Growth calculation'!G23 -> 0.033678865 | E22: 59500 | F22: 2025 | G22: projected | H22: 13090 | I22: 17010 | J22: 18030 | K22: 19310 | L22: 20580 | M22: 23170 | N22: 23410 | O22: 25090 | P22: 27070 | Q22: 28550 | R22: 28450 | S22: 26530 | T22: 25980 | U22: 25890 | V22: 24460 | W22: 24060 | X22: 27100 | Y22: 32910 | Z22: 37780 | AA22: 39940 | AB22: 42740 | AC22: 46570 | AD22: 47120 | AE22: 47110 | AF22: 46720 | AG22: 47170 | AH22: 47950 | AI22: 48050 | AJ22: 45520 | AK22: 43240 | AL22: 42310 | AM22: 45980 | AN22: 48070 | AO22: 46330 | AP22: 51140 | AQ22: 54330 | AR22: 55520 | AS22: 55290 | AT22: 59500 | AU22: =$E22*(1+$D22) -> 61503.892 | AV22: =AU22*(1+$D22) -> 63575.274 | AW22: =AV22*(1+$D22) -> 65716.417 | AX22: =AW22*(1+$D22) -> 67929.671 | AY22: =AX22*(1+$D22) -> 70217.465 | AZ22: =AY22*(1+$D22) -> 72582.31 | BA22: =AZ22*(1+$D22) -> 75026.8 | BB22: =BA22*(1+$D22) -> 77553.617 | BC22: =BB22*(1+$D22) -> 80165.535 | ... BS22: =BR22*(1+$D22) -> 136193.97
A23: Belize | B23: BLZ | C23: UM | D23: ='Growth calculation'!G24 -> 0.032319336 | E23: 7530 | F23: 2025 | G23: projected | H23: 2200 | I23: 2550 | J23: 2830 | K23: 3080 | L23: 3320 | M23: 3690 | N23: 3830 | O23: 3800 | P23: 3890 | Q23: 3910 | R23: 3950 | S23: 3860 | T23: 4060 | U23: 4470 | V23: 4470 | W23: 4550 | X23: 4820 | Y23: 5000 | Z23: 5050 | AA23: 5160 | AB23: 5210 | AC23: 5170 | AD23: 5280 | AE23: 5060 | AF23: 5160 | AG23: 5330 | AH23: 5580 | AI23: 5670 | AJ23: 5790 | AK23: 5640 | AL23: 5490 | AM23: 5610 | AN23: 5850 | AO23: 5170 | AP23: 6120 | AQ23: 6710 | AR23: 6850 | AS23: 7150 | AT23: 7530 | AU23: =$E23*(1+$D23) -> 7773.3646 | AV23: =AU23*(1+$D23) -> 8024.5946 | AW23: =AV23*(1+$D23) -> 8283.9442 | AX23: =AW23*(1+$D23) -> 8551.6757 | AY23: =AX23*(1+$D23) -> 8828.0602 | AZ23: =AY23*(1+$D23) -> 9113.3773 | BA23: =AZ23*(1+$D23) -> 9407.9156 | BB23: =BA23*(1+$D23) -> 9711.9731 | BC23: =BB23*(1+$D23) -> 10025.858 | ... BS23: =BR23*(1+$D23) -> 16678.098
A24: Benin | B24: BEN | C24: LM | D24: ='Growth calculation'!G25 -> 0.036709918 | E24: 1600 | F24: 2025 | G24: projected | H24: 290 | I24: 340 | J24: 320 | K24: 350 | L24: 360 | M24: 350 | N24: 360 | O24: 310 | P24: 340 | Q24: 330 | R24: 360 | S24: 350 | T24: 390 | U24: 450 | V24: 510 | W24: 510 | X24: 570 | Y24: 690 | Z24: 780 | AA24: 810 | AB24: 870 | AC24: 970 | AD24: 1020 | AE24: 1020 | AF24: 1030 | AG24: 1050 | AH24: 1140 | AI24: 1180 | AJ24: 1100 | AK24: 1040 | AL24: 1020 | AM24: 1120 | AN24: 1170 | AO24: 1190 | AP24: 1280 | AQ24: 1360 | AR24: 1390 | AS24: 1430 | AT24: 1600 | AU24: =$E24*(1+$D24) -> 1658.7359 | AV24: =AU24*(1+$D24) -> 1719.6279 | AW24: =AV24*(1+$D24) -> 1782.7553 | AX24: =AW24*(1+$D24) -> 1848.2001 | AY24: =AX24*(1+$D24) -> 1916.0474 | AZ24: =AY24*(1+$D24) -> 1986.3853 | BA24: =AZ24*(1+$D24) -> 2059.3054 | BB24: =BA24*(1+$D24) -> 2134.9023 | BC24: =BB24*(1+$D24) -> 2213.2744 | ... BS24: =BR24*(1+$D24) -> 3940.4998
A25: Bermuda | B25: BMU | C25: H | D25: ='Growth calculation'!G26 -> 0.032610612 | E25: 139370 | F25: 2024 | G25: projected | AE25: 105750 | AF25: 102930 | AG25: 101910 | AH25: 104040 | AI25: 102450 | AJ25: 103940 | AK25: 105430 | AL25: 113460 | AM25: 117160 | AN25: 116920 | AO25: 110850 | AP25: 120460 | AQ25: 131560 | AR25: 133460 | AS25: 139370 | AU25: =$E25*(1+$D25) -> 143914.94 | AV25: =AU25*(1+$D25) -> 148608.1 | AW25: =AV25*(1+$D25) -> 153454.3 | AX25: =AW25*(1+$D25) -> 158458.53 | AY25: =AX25*(1+$D25) -> 163625.96 | AZ25: =AY25*(1+$D25) -> 168961.91 | BA25: =AZ25*(1+$D25) -> 174471.86 | BB25: =BA25*(1+$D25) -> 180161.49 | BC25: =BB25*(1+$D25) -> 186036.67 | ... BS25: =BR25*(1+$D25) -> 310873.64
A26: Bhutan | B26: BTN | C26: LM | D26: ='Growth calculation'!G27 -> 0.05764204 | E26: 4310 | F26: 2025 | G26: projected | H26: 430 | I26: 480 | J26: 500 | K26: 500 | L26: 430 | M26: 420 | N26: 400 | O26: 430 | P26: 450 | Q26: 500 | R26: 550 | S26: 520 | T26: 550 | U26: 710 | V26: 780 | W26: 860 | X26: 960 | Y26: 1090 | Z26: 1260 | AA26: 1390 | AB26: 1700 | AC26: 1850 | AD26: 1980 | AE26: 2180 | AF26: 2430 | AG26: 2620 | AH26: 2630 | AI26: 2670 | AJ26: 2740 | AK26: 2880 | AL26: 2960 | AM26: 3150 | AN26: 3370 | AO26: 3040 | AP26: 3300 | AQ26: 3600 | AR26: 3730 | AS26: 3910 | AT26: 4310 | AU26: =$E26*(1+$D26) -> 4558.4372 | AV26: =AU26*(1+$D26) -> 4821.1948 | AW26: =AV26*(1+$D26) -> 5099.0983 | AX26: =AW26*(1+$D26) -> 5393.0207 | AY26: =AX26*(1+$D26) -> 5703.8855 | AZ26: =AY26*(1+$D26) -> 6032.6691 | BA26: =AZ26*(1+$D26) -> 6380.4044 | BB26: =BA26*(1+$D26) -> 6748.1839 | BC26: =BB26*(1+$D26) -> 7137.163 | ... BS26: =BR26*(1+$D26) -> 17496.247
A27: Bolivia | B27: BOL | C27: LM | D27: ='Growth calculation'!G28 -> 0.056312657 | E27: 4420 | F27: 2025 | G27: projected | H27: 690 | I27: 690 | J27: 690 | K27: 690 | L27: 710 | M27: 740 | N27: 760 | O27: 790 | P27: 820 | Q27: 870 | R27: 930 | S27: 960 | T27: 950 | U27: 960 | V27: 930 | W27: 900 | X27: 890 | Y27: 940 | Z27: 1000 | AA27: 1090 | AB27: 1210 | AC27: 1460 | AD27: 1600 | AE27: 1760 | AF27: 1970 | AG27: 2220 | AH27: 2550 | AI27: 2800 | AJ27: 2920 | AK27: 3000 | AL27: 3250 | AM27: 3730 | AN27: 4170 | AO27: 3620 | AP27: 3990 | AQ27: 4190 | AR27: 4230 | AS27: 4160 | AT27: 4420 | AU27: =$E27*(1+$D27) -> 4668.9019 | AV27: =AU27*(1+$D27) -> 4931.8202 | AW27: =AV27*(1+$D27) -> 5209.5441 | AX27: =AW27*(1+$D27) -> 5502.9074 | AY27: =AX27*(1+$D27) -> 5812.7907 | AZ27: =AY27*(1+$D27) -> 6140.1244 | BA27: =AZ27*(1+$D27) -> 6485.8911 | BB27: =BA27*(1+$D27) -> 6851.1289 | BC27: =BB27*(1+$D27) -> 7236.9341 | ... BS27: =BR27*(1+$D27) -> 17387.388
A28: Bosnia and Herzegovina | B28: BIH | C28: UM | D28: ='Growth calculation'!G29 -> 0.077174771 | E28: 9940 | F28: 2025 | G28: projected | M28: 1140 | N28: 980 | O28: 580 | P28: 510 | Q28: 640 | R28: 900 | S28: 1230 | T28: 1270 | U28: 1340 | V28: 1430 | W28: 1590 | X28: 1860 | Y28: 2360 | Z28: 2810 | AA28: 3160 | AB28: 3680 | AC28: 4500 | AD28: 4790 | AE28: 4820 | AF28: 4900 | AG28: 4900 | AH28: 5170 | AI28: 5180 | AJ28: 5140 | AK28: 5070 | AL28: 5070 | AM28: 5720 | AN28: 6180 | AO28: 6160 | AP28: 6970 | AQ28: 7710 | AR28: 8280 | AS28: 8810 | AT28: 9940 | AU28: =$E28*(1+$D28) -> 10707.117 | AV28: =AU28*(1+$D28) -> 11533.437 | AW28: =AV28*(1+$D28) -> 12423.527 | AX28: =AW28*(1+$D28) -> 13382.31 | AY28: =AX28*(1+$D28) -> 14415.086 | AZ28: =AY28*(1+$D28) -> 15527.567 | BA28: =AZ28*(1+$D28) -> 16725.904 | BB28: =BA28*(1+$D28) -> 18016.722 | BC28: =BB28*(1+$D28) -> 19407.158 | ... BS28: =BR28*(1+$D28) -> 63758.884
A29: Botswana | B29: BWA | C29: UM | D29: ='Growth calculation'!G30 -> 0.029177313 | E29: 7390 | F29: 2025 | G29: projected | H29: 1290 | I29: 1930 | J29: 2270 | K29: 2680 | L29: 3030 | M29: 3230 | N29: 3280 | O29: 2900 | P29: 3200 | Q29: 3120 | R29: 3260 | S29: 3150 | T29: 3090 | U29: 3110 | V29: 3190 | W29: 2860 | X29: 3300 | Y29: 3830 | Z29: 4830 | AA29: 5400 | AB29: 5620 | AC29: 5470 | AD29: 4890 | AE29: 5370 | AF29: 6500 | AG29: 6680 | AH29: 6950 | AI29: 6990 | AJ29: 6140 | AK29: 6060 | AL29: 6210 | AM29: 6680 | AN29: 7100 | AO29: 6600 | AP29: 7440 | AQ29: 7690 | AR29: 8150 | AS29: 7610 | AT29: 7390 | AU29: =$E29*(1+$D29) -> 7605.6203 | AV29: =AU29*(1+$D29) -> 7827.5319 | AW29: =AV29*(1+$D29) -> 8055.9183 | AX29: =AW29*(1+$D29) -> 8290.9683 | AY29: =AX29*(1+$D29) -> 8532.8765 | AZ29: =AY29*(1+$D29) -> 8781.8429 | BA29: =AZ29*(1+$D29) -> 9038.0735 | BB29: =BA29*(1+$D29) -> 9301.7802 | BC29: =BB29*(1+$D29) -> 9573.1811 | ... BS29: =BR29*(1+$D29) -> 15166.995
A30: Brazil | B30: BRA | C30: UM | D30: ='Growth calculation'!G31 -> 0.028401527 | E30: 10550 | F30: 2025 | G30: projected | H30: 2030 | I30: 2300 | J30: 2630 | K30: 2470 | L30: 2510 | M30: 2330 | N30: 2310 | O30: 2620 | P30: 3440 | Q30: 4420 | R30: 5110 | S30: 4980 | T30: 4230 | U30: 3950 | V30: 3370 | W30: 3120 | X30: 3010 | Y30: 3370 | Z30: 4030 | AA30: 4890 | AB30: 6240 | AC30: 7680 | AD30: 8400 | AE30: 9750 | AF30: 11210 | AG30: 12460 | AH30: 12950 | AI30: 12280 | AJ30: 10330 | AK30: 9050 | AL30: 8830 | AM30: 9320 | AN30: 9410 | AO30: 8080 | AP30: 8060 | AQ30: 8440 | AR30: 9310 | AS30: 9930 | AT30: 10550 | AU30: =$E30*(1+$D30) -> 10849.636 | AV30: =AU30*(1+$D30) -> 11157.782 | AW30: =AV30*(1+$D30) -> 11474.68 | AX30: =AW30*(1+$D30) -> 11800.579 | AY30: =AX30*(1+$D30) -> 12135.733 | AZ30: =AY30*(1+$D30) -> 12480.407 | BA30: =AZ30*(1+$D30) -> 12834.869 | BB30: =BA30*(1+$D30) -> 13199.399 | BC30: =BB30*(1+$D30) -> 13574.282 | ... BS30: =BR30*(1+$D30) -> 21248.109
A31: British Virgin Islands | B31: VGB | C31: H | G31: frozen - only 0 of 10 annual rates
A32: Brunei Darussalam | B32: BRN | C32: H | D32: ='Growth calculation'!G33 -> 0.01244 | E32: 34790 | F32: 2025 | G32: projected - raised from -1.9% to the 1.244% floor | J32: 20550 | K32: 21430 | L32: 23400 | M32: 23920 | N32: 23250 | O32: 23220 | P32: 24460 | Q32: 25200 | R32: 26590 | S32: 21000 | T32: 19960 | U32: 19390 | V32: 19270 | W32: 18960 | X32: 19840 | Y32: 22190 | Z32: 25670 | AA32: 30720 | AB32: 33470 | AC32: 36700 | AD32: 35470 | AE32: 35370 | AF32: 36520 | AG32: 41690 | AH32: 44580 | AI32: 42370 | AJ32: 38180 | AK32: 32570 | AL32: 29230 | AM32: 28790 | AN32: 31550 | AO32: 30810 | AP32: 29890 | AQ32: 30970 | AR32: 34390 | AS32: 36020 | AT32: 34790 | AU32: =$E32*(1+$D32) -> 35222.788 | AV32: =AU32*(1+$D32) -> 35660.959 | AW32: =AV32*(1+$D32) -> 36104.581 | AX32: =AW32*(1+$D32) -> 36553.722 | AY32: =AX32*(1+$D32) -> 37008.451 | AZ32: =AY32*(1+$D32) -> 37468.836 | BA32: =AZ32*(1+$D32) -> 37934.948 | BB32: =BA32*(1+$D32) -> 38406.859 | BC32: =BB32*(1+$D32) -> 38884.64 | ... BS32: =BR32*(1+$D32) -> 47390.011
A33: Bulgaria | B33: BGR | C33: H | D33: ='Growth calculation'!G34 -> 0.071689 | E33: 17780 | F33: 2025 | G33: projected - cut from 10.2% to the H p90 cap of 7.17% | H33: 2750 | I33: 3140 | J33: 2850 | K33: 2260 | L33: 1340 | M33: 1150 | N33: 1030 | O33: 1170 | P33: 1520 | Q33: 1590 | R33: 1460 | S33: 1440 | T33: 1480 | U33: 1660 | V33: 1770 | W33: 1970 | X33: 2370 | Y33: 3060 | Z33: 3800 | AA33: 4300 | AB33: 4820 | AC33: 6080 | AD33: 6680 | AE33: 6960 | AF33: 7210 | AG33: 7400 | AH33: 7580 | AI33: 7780 | AJ33: 7530 | AK33: 7490 | AL33: 7730 | AM33: 8860 | AN33: 9920 | AO33: 10090 | AP33: 11720 | AQ33: 13100 | AR33: 14240 | AS33: 15370 | AT33: 17780 | AU33: =$E33*(1+$D33) -> 19054.63 | AV33: =AU33*(1+$D33) -> 20420.638 | AW33: =AV33*(1+$D33) -> 21884.573 | AX33: =AW33*(1+$D33) -> 23453.456 | AY33: =AX33*(1+$D33) -> 25134.811 | AZ33: =AY33*(1+$D33) -> 26936.7 | BA33: =AZ33*(1+$D33) -> 28867.765 | BB33: =BA33*(1+$D33) -> 30937.267 | BC33: =BB33*(1+$D33) -> 33155.128 | ... BS33: =BR33*(1+$D33) -> 100380.9
A34: Burkina Faso | B34: BFA | C34: L | D34: ='Growth calculation'!G35 -> 0.025893752 | E34: 980 | F34: 2025 | G34: projected | H34: 260 | I34: 310 | J34: 320 | K34: 320 | L34: 340 | M34: 360 | N34: 350 | O34: 270 | P34: 250 | Q34: 240 | R34: 250 | S34: 240 | T34: 260 | U34: 260 | V34: 270 | W34: 260 | X34: 310 | Y34: 370 | Z34: 440 | AA34: 470 | AB34: 490 | AC34: 550 | AD34: 590 | AE34: 630 | AF34: 660 | AG34: 710 | AH34: 750 | AI34: 730 | AJ34: 680 | AK34: 650 | AL34: 650 | AM34: 730 | AN34: 750 | AO34: 780 | AP34: 820 | AQ34: 840 | AR34: 840 | AS34: 850 | AT34: 980 | AU34: =$E34*(1+$D34) -> 1005.3759 | AV34: =AU34*(1+$D34) -> 1031.4088 | AW34: =AV34*(1+$D34) -> 1058.1159 | AX34: =AW34*(1+$D34) -> 1085.5145 | AY34: =AX34*(1+$D34) -> 1113.6225 | AZ34: =AY34*(1+$D34) -> 1142.4584 | BA34: =AZ34*(1+$D34) -> 1172.0409 | BB34: =BA34*(1+$D34) -> 1202.3894 | BC34: =BB34*(1+$D34) -> 1233.5238 | ... BS34: =BR34*(1+$D34) -> 1856.8879
A35: Burundi | B35: BDI | C35: L | D35: ='Growth calculation'!G36 -> 0.01244 | E35: 240 | F35: 2025 | G35: projected - raised from 0.0% to the 1.244% floor | H35: 250 | I35: 240 | J35: 220 | K35: 210 | L35: 210 | M35: 200 | N35: 180 | O35: 170 | P35: 150 | Q35: 140 | R35: 150 | S35: 150 | T35: 140 | U35: 130 | V35: 130 | W35: 130 | X35: 120 | Y35: 120 | Z35: 130 | AA35: 150 | AB35: 160 | AC35: 180 | AD35: 190 | AE35: 200 | AF35: 220 | AG35: 230 | AH35: 240 | AI35: 240 | AJ35: 240 | AK35: 240 | AL35: 240 | AM35: 250 | AN35: 250 | AO35: 240 | AP35: 250 | AQ35: 280 | AR35: 280 | AS35: 250 | AT35: 240 | AU35: =$E35*(1+$D35) -> 242.9856 | AV35: =AU35*(1+$D35) -> 246.00834 | AW35: =AV35*(1+$D35) -> 249.06868 | AX35: =AW35*(1+$D35) -> 252.1671 | AY35: =AX35*(1+$D35) -> 255.30406 | AZ35: =AY35*(1+$D35) -> 258.48004 | BA35: =AZ35*(1+$D35) -> 261.69553 | BB35: =BA35*(1+$D35) -> 264.95102 | BC35: =BB35*(1+$D35) -> 268.24702 | ... BS35: =BR35*(1+$D35) -> 326.9216
A36: Cabo Verde | B36: CPV | C36: UM | D36: ='Growth calculation'!G37 -> 0.068126749 | E36: 5590 | F36: 2025 | G36: projected | H36: 580 | I36: 750 | J36: 810 | K36: 810 | L36: 820 | M36: 940 | N36: 1080 | O36: 1190 | P36: 1300 | Q36: 1250 | R36: 1260 | S36: 1240 | T36: 1290 | U36: 1330 | V36: 1270 | W36: 1230 | X36: 1440 | Y36: 1810 | Z36: 2070 | AA36: 2200 | AB36: 2770 | AC36: 3360 | AD36: 3650 | AE36: 3600 | AF36: 3760 | AG36: 3730 | AH36: 3840 | AI36: 3750 | AJ36: 3620 | AK36: 3580 | AL36: 3620 | AM36: 4040 | AN36: 4420 | AO36: 3510 | AP36: 3870 | AQ36: 4550 | AR36: 4740 | AS36: 4940 | AT36: 5590 | AU36: =$E36*(1+$D36) -> 5970.8285 | AV36: =AU36*(1+$D36) -> 6377.6017 | AW36: =AV36*(1+$D36) -> 6812.0869 | AX36: =AW36*(1+$D36) -> 7276.1723 | AY36: =AX36*(1+$D36) -> 7771.8742 | AZ36: =AY36*(1+$D36) -> 8301.3468 | BA36: =AZ36*(1+$D36) -> 8866.8905 | BB36: =BA36*(1+$D36) -> 9470.963 | BC36: =BB36*(1+$D36) -> 10116.189 | ... BS36: =BR36*(1+$D36) -> 29038.996
A37: Cambodia | B37: KHM | C37: LM | D37: ='Growth calculation'!G38 -> 0.074593045 | E37: 2750 | F37: 2025 | G37: projected | H37: 160 | I37: 190 | J37: 170 | K37: 170 | L37: 170 | M37: 210 | N37: 290 | O37: 210 | P37: 260 | Q37: 320 | R37: 310 | S37: 280 | T37: 290 | U37: 290 | V37: 310 | W37: 320 | X37: 370 | Y37: 430 | Z37: 510 | AA37: 580 | AB37: 670 | AC37: 780 | AD37: 840 | AE37: 910 | AF37: 990 | AG37: 1110 | AH37: 1230 | AI37: 1330 | AJ37: 1430 | AK37: 1550 | AL37: 1690 | AM37: 1920 | AN37: 2100 | AO37: 2050 | AP37: 2120 | AQ37: 2270 | AR37: 2390 | AS37: 2550 | AT37: 2750 | AU37: =$E37*(1+$D37) -> 2955.1309 | AV37: =AU37*(1+$D37) -> 3175.5631 | AW37: =AV37*(1+$D37) -> 3412.438 | AX37: =AW37*(1+$D37) -> 3666.9821 | AY37: =AX37*(1+$D37) -> 3940.5135 | AZ37: =AY37*(1+$D37) -> 4234.4484 | BA37: =AZ37*(1+$D37) -> 4550.3088 | BB37: =BA37*(1+$D37) -> 4889.7302 | BC37: =BB37*(1+$D37) -> 5254.4701 | ... BS37: =BR37*(1+$D37) -> 16612.436
A38: Cameroon | B38: CMR | C38: LM | D38: ='Growth calculation'!G39 -> 0.019181991 | E38: 1860 | F38: 2025 | G38: projected | H38: 1150 | I38: 1230 | J38: 1120 | K38: 1000 | L38: 930 | M38: 960 | N38: 990 | O38: 890 | P38: 870 | Q38: 770 | R38: 790 | S38: 770 | T38: 760 | U38: 730 | V38: 700 | W38: 700 | X38: 820 | Y38: 1030 | Z38: 1140 | AA38: 1200 | AB38: 1250 | AC38: 1360 | AD38: 1460 | AE38: 1450 | AF38: 1470 | AG38: 1470 | AH38: 1530 | AI38: 1570 | AJ38: 1530 | AK38: 1470 | AL38: 1410 | AM38: 1520 | AN38: 1560 | AO38: 1540 | AP38: 1610 | AQ38: 1660 | AR38: 1680 | AS38: 1690 | AT38: 1860 | AU38: =$E38*(1+$D38) -> 1895.6785 | AV38: =AU38*(1+$D38) -> 1932.0414 | AW38: =AV38*(1+$D38) -> 1969.1018 | AX38: =AW38*(1+$D38) -> 2006.8731 | AY38: =AX38*(1+$D38) -> 2045.3689 | AZ38: =AY38*(1+$D38) -> 2084.6032 | BA38: =AZ38*(1+$D38) -> 2124.59 | BB38: =BA38*(1+$D38) -> 2165.3439 | BC38: =BB38*(1+$D38) -> 2206.8795 | ... BS38: =BR38*(1+$D38) -> 2990.9315
A39: Canada | B39: CAN | C39: H | D39: ='Growth calculation'!G40 -> 0.028610436 | E39: 56420 | F39: 2025 | G39: projected | H39: 16320 | I39: 18620 | J39: 19860 | K39: 20650 | L39: 20990 | M39: 21420 | N39: 21270 | O39: 20890 | P39: 20850 | Q39: 20820 | R39: 21330 | S39: 20900 | T39: 21450 | U39: 22740 | V39: 23120 | W39: 23590 | X39: 25480 | Y39: 29530 | Z39: 34310 | AA39: 37900 | AB39: 41540 | AC39: 44930 | AD39: 43230 | AE39: 44490 | AF39: 47190 | AG39: 51080 | AH39: 52800 | AI39: 52200 | AJ39: 47580 | AK39: 43900 | AL39: 42900 | AM39: 45060 | AN39: 46580 | AO39: 43900 | AP39: 49080 | AQ39: 54070 | AR39: 55340 | AS39: 54110 | AT39: 56420 | AU39: =$E39*(1+$D39) -> 58034.201 | AV39: =AU39*(1+$D39) -> 59694.585 | AW39: =AV39*(1+$D39) -> 61402.473 | AX39: =AW39*(1+$D39) -> 63159.224 | AY39: =AX39*(1+$D39) -> 64966.237 | AZ39: =AY39*(1+$D39) -> 66824.949 | BA39: =AZ39*(1+$D39) -> 68736.84 | BB39: =BA39*(1+$D39) -> 70703.431 | BC39: =BB39*(1+$D39) -> 72726.287 | ... BS39: =BR39*(1+$D39) -> 114210.55
A40: Cayman Islands | B40: CYM | C40: H | D40: ='Growth calculation'!G41 -> 0.071689 | E40: 81920 | F40: 2024 | G40: projected - cut from 8.5% to the H p90 cap of 7.17% | AE40: 73550 | AF40: 73950 | AG40: 51150 | AH40: 44990 | AI40: 43420 | AJ40: 44430 | AK40: 47830 | AL40: 51890 | AM40: 57880 | AN40: 64520 | AO40: 62420 | AP40: 76260 | AQ40: 73960 | AR40: 73970 | AS40: 81920 | AU40: =$E40*(1+$D40) -> 87792.763 | AV40: =AU40*(1+$D40) -> 94086.538 | AW40: =AV40*(1+$D40) -> 100831.51 | AX40: =AW40*(1+$D40) -> 108060.02 | AY40: =AX40*(1+$D40) -> 115806.73 | AZ40: =AY40*(1+$D40) -> 124108.8 | BA40: =AZ40*(1+$D40) -> 133006.04 | BB40: =BA40*(1+$D40) -> 142541.11 | BC40: =BB40*(1+$D40) -> 152759.74 | ... BS40: =BR40*(1+$D40) -> 462497.37
A41: Central African Republic | B41: CAF | C41: L | D41: ='Growth calculation'!G42 -> 0.033228676 | E41: 560 | F41: 2025 | G41: projected | H41: 410 | I41: 480 | J41: 480 | K41: 470 | L41: 460 | M41: 460 | N41: 430 | O41: 360 | P41: 340 | Q41: 290 | R41: 290 | S41: 270 | T41: 260 | U41: 240 | V41: 240 | W41: 240 | X41: 250 | Y41: 290 | Z41: 320 | AA41: 330 | AB41: 360 | AC41: 390 | AD41: 460 | AE41: 500 | AF41: 510 | AG41: 540 | AH41: 360 | AI41: 380 | AJ41: 390 | AK41: 400 | AL41: 420 | AM41: 470 | AN41: 500 | AO41: 490 | AP41: 510 | AQ41: 520 | AR41: 530 | AS41: 510 | AT41: 560 | AU41: =$E41*(1+$D41) -> 578.60806 | AV41: =AU41*(1+$D41) -> 597.83444 | AW41: =AV41*(1+$D41) -> 617.69969 | AX41: =AW41*(1+$D41) -> 638.22503 | AY41: =AX41*(1+$D41) -> 659.4324 | AZ41: =AY41*(1+$D41) -> 681.34447 | BA41: =AZ41*(1+$D41) -> 703.98464 | BB41: =BA41*(1+$D41) -> 727.37712 | BC41: =BB41*(1+$D41) -> 751.5469 | ... BS41: =BR41*(1+$D41) -> 1267.9418
...

Sheet Growth calculation
A1: Growth rate: the median of the ten annual rates to 2025, then the floor and the cap applied | E1: raised by floor | F1: =COUNTIF(H5:H222,"raised by floor") -> 37 | H1: cut by cap | I1: =COUNTIF(H5:H222,"cut by cap") -> 21 | K1: unadjusted | L1: =COUNTIF(H5:H222,"unadjusted") -> 139 | N1: frozen | O1: =COUNTIF(H5:H222,"frozen") -> 21
A4: Economy | B4: Code | C4: 2025 class | D4: Median, last 10 years | E4: Floor | F4: Cap | G4: Rate used | H4: Adjustment | I4: Change | J4: Obs | K4: 2016 | L4: 2017 | M4: 2018 | N4: 2019 | O4: 2020 | P4: 2021 | Q4: 2022 | R4: 2023 | S4: 2024 | T4: 2025 | U4: Status
A5: Afghanistan | B5: AFG | C5: L | D5: =IFERROR(MEDIAN(K5:T5),"") -> -0.026315789 | E5: =Assumptions!$C$5 -> 0.01244 | F5: =IF($C5="L",Assumptions!$C$8,IF($C5="LM",Assumptions!$C$9,IF($C5="UM",Assumptions!$C$10,Assumptions!$C$11))) -> 0.055948 | G5: =IF(J5<Assumptions!$C$13,"",MIN(MAX(D5,E5),F5)) -> 0.01244 | H5: =IF(G5="","frozen",IF(ROUND(G5-D5,8)>0,"raised by floor",IF(ROUND(G5-D5,8)<0,"cut by cap","unadjusted"))) -> raised by floor | I5: =IF(OR(G5="",D5=""),"",G5-D5) -> 0.038755789 | J5: =COUNT(K5:T5) -> 9 | K5: =IF(OR('GNI per capita'!AJ4="",'GNI per capita'!AK4=""),"",'GNI per capita'!AK4/'GNI per capita'!AJ4-1) -> -0.050847458 | L5: =IF(OR('GNI per capita'!AK4="",'GNI per capita'!AL4=""),"",'GNI per capita'!AL4/'GNI per capita'!AK4-1) -> -0.053571429 | M5: =IF(OR('GNI per capita'!AL4="",'GNI per capita'!AM4=""),"",'GNI per capita'!AM4/'GNI per capita'!AL4-1) -> -0.018867925 | N5: =IF(OR('GNI per capita'!AM4="",'GNI per capita'!AN4=""),"",'GNI per capita'!AN4/'GNI per capita'!AM4-1) -> 0 | O5: =IF(OR('GNI per capita'!AN4="",'GNI per capita'!AO4=""),"",'GNI per capita'!AO4/'GNI per capita'!AN4-1) -> -0.057692308 | P5: =IF(OR('GNI per capita'!AO4="",'GNI per capita'!AP4=""),"",'GNI per capita'!AP4/'GNI per capita'!AO4-1) -> -0.2244898 | Q5: =IF(OR('GNI per capita'!AP4="",'GNI per capita'!AQ4=""),"",'GNI per capita'!AQ4/'GNI per capita'!AP4-1) -> -0.026315789 | R5: =IF(OR('GNI per capita'!AQ4="",'GNI per capita'!AR4=""),"",'GNI per capita'!AR4/'GNI per capita'!AQ4-1) -> 0 | ... T5: =IF(OR('GNI per capita'!AS4="",'GNI per capita'!AT4=""),"",'GNI per capita'!AT4/'GNI per capita'!AS4-1) | U5: projected - raised from -2.6% to the 1.244% floor
A6: Albania | B6: ALB | C6: UM | D6: =IFERROR(MEDIAN(K6:T6),"") -> 0.12225814 | E6: =Assumptions!$C$5 -> 0.01244 | F6: =IF($C6="L",Assumptions!$C$8,IF($C6="LM",Assumptions!$C$9,IF($C6="UM",Assumptions!$C$10,Assumptions!$C$11))) -> 0.090712 | G6: =IF(J6<Assumptions!$C$13,"",MIN(MAX(D6,E6),F6)) -> 0.090712 | H6: =IF(G6="","frozen",IF(ROUND(G6-D6,8)>0,"raised by floor",IF(ROUND(G6-D6,8)<0,"cut by cap","unadjusted"))) -> cut by cap | I6: =IF(OR(G6="",D6=""),"",G6-D6) -> -0.031546142 | J6: =COUNT(K6:T6) -> 10 | K6: =IF(OR('GNI per capita'!AJ5="",'GNI per capita'!AK5=""),"",'GNI per capita'!AK5/'GNI per capita'!AJ5-1) -> 0.0021459227 | L6: =IF(OR('GNI per capita'!AK5="",'GNI per capita'!AL5=""),"",'GNI per capita'!AL5/'GNI per capita'!AK5-1) -> 0.0064239829 | M6: =IF(OR('GNI per capita'!AL5="",'GNI per capita'!AM5=""),"",'GNI per capita'!AM5/'GNI per capita'!AL5-1) -> 0.14893617 | N6: =IF(OR('GNI per capita'!AM5="",'GNI per capita'!AN5=""),"",'GNI per capita'!AN5/'GNI per capita'!AM5-1) -> 0.092592593 | O6: =IF(OR('GNI per capita'!AN5="",'GNI per capita'!AO5=""),"",'GNI per capita'!AO5/'GNI per capita'!AN5-1) -> 0.011864407 | P6: =IF(OR('GNI per capita'!AO5="",'GNI per capita'!AP5=""),"",'GNI per capita'!AP5/'GNI per capita'!AO5-1) -> 0.16247906 | Q6: =IF(OR('GNI per capita'!AP5="",'GNI per capita'!AQ5=""),"",'GNI per capita'!AQ5/'GNI per capita'!AP5-1) -> 0.11239193 | R6: =IF(OR('GNI per capita'!AQ5="",'GNI per capita'!AR5=""),"",'GNI per capita'!AR5/'GNI per capita'!AQ5-1) -> 0.13212435 | ... T6: =IF(OR('GNI per capita'!AS5="",'GNI per capita'!AT5=""),"",'GNI per capita'!AT5/'GNI per capita'!AS5-1) -> 0.21695257 | U6: projected - cut from 12.2% to the UM p90 cap of 9.07%
A7: Algeria | B7: DZA | C7: UM | D7: =IFERROR(MEDIAN(K7:T7),"") -> 0.015808597 | E7: =Assumptions!$C$5 -> 0.01244 | F7: =IF($C7="L",Assumptions!$C$8,IF($C7="LM",Assumptions!$C$9,IF($C7="UM",Assumptions!$C$10,Assumptions!$C$11))) -> 0.090712 | G7: =IF(J7<Assumptions!$C$13,"",MIN(MAX(D7,E7),F7)) -> 0.015808597 | H7: =IF(G7="","frozen",IF(ROUND(G7-D7,8)>0,"raised by floor",IF(ROUND(G7-D7,8)<0,"cut by cap","unadjusted"))) -> unadjusted | I7: =IF(OR(G7="",D7=""),"",G7-D7) -> 0 | J7: =COUNT(K7:T7) -> 10 | K7: =IF(OR('GNI per capita'!AJ6="",'GNI per capita'!AK6=""),"",'GNI per capita'!AK6/'GNI per capita'!AJ6-1) -> -0.087198516 | L7: =IF(OR('GNI per capita'!AK6="",'GNI per capita'!AL6=""),"",'GNI per capita'!AL6/'GNI per capita'!AK6-1) -> -0.097560976 | M7: =IF(OR('GNI per capita'!AL6="",'GNI per capita'!AM6=""),"",'GNI per capita'!AM6/'GNI per capita'!AL6-1) -> 0.0022522523 | N7: =IF(OR('GNI per capita'!AM6="",'GNI per capita'!AN6=""),"",'GNI per capita'!AN6/'GNI per capita'!AM6-1) -> 0.006741573 | O7: =IF(OR('GNI per capita'!AN6="",'GNI per capita'!AO6=""),"",'GNI per capita'!AO6/'GNI per capita'!AN6-1) -> -0.10267857 | P7: =IF(OR('GNI per capita'!AO6="",'GNI per capita'!AP6=""),"",'GNI per capita'!AP6/'GNI per capita'!AO6-1) -> 0.024875622 | Q7: =IF(OR('GNI per capita'!AP6="",'GNI per capita'!AQ6=""),"",'GNI per capita'!AQ6/'GNI per capita'!AP6-1) -> 0.075242718 | R7: =IF(OR('GNI per capita'!AQ6="",'GNI per capita'!AR6=""),"",'GNI per capita'!AR6/'GNI per capita'!AQ6-1) -> 0.11738149 | ... T7: =IF(OR('GNI per capita'!AS6="",'GNI per capita'!AT6=""),"",'GNI per capita'!AT6/'GNI per capita'!AS6-1) -> 0.089385475 | U7: projected
A8: American Samoa | B8: ASM | C8: H | D8: =IFERROR(MEDIAN(K8:T8),"") | E8: =Assumptions!$C$5 -> 0.01244 | F8: =IF($C8="L",Assumptions!$C$8,IF($C8="LM",Assumptions!$C$9,IF($C8="UM",Assumptions!$C$10,Assumptions!$C$11))) -> 0.071689 | G8: =IF(J8<Assumptions!$C$13,"",MIN(MAX(D8,E8),F8)) | H8: =IF(G8="","frozen",IF(ROUND(G8-D8,8)>0,"raised by floor",IF(ROUND(G8-D8,8)<0,"cut by cap","unadjusted"))) -> frozen | I8: =IF(OR(G8="",D8=""),"",G8-D8) | J8: =COUNT(K8:T8) -> 0 | K8: =IF(OR('GNI per capita'!AJ7="",'GNI per capita'!AK7=""),"",'GNI per capita'!AK7/'GNI per capita'!AJ7-1) | L8: =IF(OR('GNI per capita'!AK7="",'GNI per capita'!AL7=""),"",'GNI per capita'!AL7/'GNI per capita'!AK7-1) | M8: =IF(OR('GNI per capita'!AL7="",'GNI per capita'!AM7=""),"",'GNI per capita'!AM7/'GNI per capita'!AL7-1) | N8: =IF(OR('GNI per capita'!AM7="",'GNI per capita'!AN7=""),"",'GNI per capita'!AN7/'GNI per capita'!AM7-1) | O8: =IF(OR('GNI per capita'!AN7="",'GNI per capita'!AO7=""),"",'GNI per capita'!AO7/'GNI per capita'!AN7-1) | P8: =IF(OR('GNI per capita'!AO7="",'GNI per capita'!AP7=""),"",'GNI per capita'!AP7/'GNI per capita'!AO7-1) | Q8: =IF(OR('GNI per capita'!AP7="",'GNI per capita'!AQ7=""),"",'GNI per capita'!AQ7/'GNI per capita'!AP7-1) | R8: =IF(OR('GNI per capita'!AQ7="",'GNI per capita'!AR7=""),"",'GNI per capita'!AR7/'GNI per capita'!AQ7-1) | ... T8: =IF(OR('GNI per capita'!AS7="",'GNI per capita'!AT7=""),"",'GNI per capita'!AT7/'GNI per capita'!AS7-1) | U8: frozen - only 0 of 10 annual rates
A9: Andorra | B9: AND | C9: H | D9: =IFERROR(MEDIAN(K9:T9),"") -> 0.030098683 | E9: =Assumptions!$C$5 -> 0.01244 | F9: =IF($C9="L",Assumptions!$C$8,IF($C9="LM",Assumptions!$C$9,IF($C9="UM",Assumptions!$C$10,Assumptions!$C$11))) -> 0.071689 | G9: =IF(J9<Assumptions!$C$13,"",MIN(MAX(D9,E9),F9)) | H9: =IF(G9="","frozen",IF(ROUND(G9-D9,8)>0,"raised by floor",IF(ROUND(G9-D9,8)<0,"cut by cap","unadjusted"))) -> frozen | I9: =IF(OR(G9="",D9=""),"",G9-D9) | J9: =COUNT(K9:T9) -> 6 | K9: =IF(OR('GNI per capita'!AJ8="",'GNI per capita'!AK8=""),"",'GNI per capita'!AK8/'GNI per capita'!AJ8-1) | L9: =IF(OR('GNI per capita'!AK8="",'GNI per capita'!AL8=""),"",'GNI per capita'!AL8/'GNI per capita'!AK8-1) | M9: =IF(OR('GNI per capita'!AL8="",'GNI per capita'!AM8=""),"",'GNI per capita'!AM8/'GNI per capita'!AL8-1) | N9: =IF(OR('GNI per capita'!AM8="",'GNI per capita'!AN8=""),"",'GNI per capita'!AN8/'GNI per capita'!AM8-1) | O9: =IF(OR('GNI per capita'!AN8="",'GNI per capita'!AO8=""),"",'GNI per capita'!AO8/'GNI per capita'!AN8-1) -> -0.086114101 | P9: =IF(OR('GNI per capita'!AO8="",'GNI per capita'!AP8=""),"",'GNI per capita'!AP8/'GNI per capita'!AO8-1) -> 0.053474676 | Q9: =IF(OR('GNI per capita'!AP8="",'GNI per capita'!AQ8=""),"",'GNI per capita'!AQ8/'GNI per capita'!AP8-1) -> 0.064400716 | R9: =IF(OR('GNI per capita'!AQ8="",'GNI per capita'!AR8=""),"",'GNI per capita'!AR8/'GNI per capita'!AQ8-1) -> 0.0067226891 | ... T9: =IF(OR('GNI per capita'!AS8="",'GNI per capita'!AT8=""),"",'GNI per capita'!AT8/'GNI per capita'!AS8-1) -> 0.11499791 | U9: frozen - only 6 of 10 annual rates
A10: Angola | B10: AGO | C10: LM | D10: =IFERROR(MEDIAN(K10:T10),"") -> -0.008245614 | E10: =Assumptions!$C$5 -> 0.01244 | F10: =IF($C10="L",Assumptions!$C$8,IF($C10="LM",Assumptions!$C$9,IF($C10="UM",Assumptions!$C$10,Assumptions!$C$11))) -> 0.074681 | G10: =IF(J10<Assumptions!$C$13,"",MIN(MAX(D10,E10),F10)) -> 0.01244 | H10: =IF(G10="","frozen",IF(ROUND(G10-D10,8)>0,"raised by floor",IF(ROUND(G10-D10,8)<0,"cut by cap","unadjusted"))) -> raised by floor | I10: =IF(OR(G10="",D10=""),"",G10-D10) -> 0.020685614 | J10: =COUNT(K10:T10) -> 10 | K10: =IF(OR('GNI per capita'!AJ9="",'GNI per capita'!AK9=""),"",'GNI per capita'!AK9/'GNI per capita'!AJ9-1) -> -0.33483146 | L10: =IF(OR('GNI per capita'!AK9="",'GNI per capita'!AL9=""),"",'GNI per capita'!AL9/'GNI per capita'!AK9-1) -> -0.17567568 | M10: =IF(OR('GNI per capita'!AL9="",'GNI per capita'!AM9=""),"",'GNI per capita'!AM9/'GNI per capita'!AL9-1) -> -0.057377049 | N10: =IF(OR('GNI per capita'!AM9="",'GNI per capita'!AN9=""),"",'GNI per capita'!AN9/'GNI per capita'!AM9-1) -> 0.069565217 | O10: =IF(OR('GNI per capita'!AN9="",'GNI per capita'!AO9=""),"",'GNI per capita'!AO9/'GNI per capita'!AN9-1) -> -0.18699187 | P10: =IF(OR('GNI per capita'!AO9="",'GNI per capita'!AP9=""),"",'GNI per capita'!AP9/'GNI per capita'!AO9-1) -> -0.02 | Q10: =IF(OR('GNI per capita'!AP9="",'GNI per capita'!AQ9=""),"",'GNI per capita'!AQ9/'GNI per capita'!AP9-1) -> 0.16836735 | R10: =IF(OR('GNI per capita'!AQ9="",'GNI per capita'!AR9=""),"",'GNI per capita'!AR9/'GNI per capita'!AQ9-1) -> 0.15720524 | ... T10: =IF(OR('GNI per capita'!AS9="",'GNI per capita'!AT9=""),"",'GNI per capita'!AT9/'GNI per capita'!AS9-1) -> 0.0035087719 | U10: projected - raised from -0.8% to the 1.244% floor
A11: Antigua and Barbuda | B11: ATG | C11: H | D11: =IFERROR(MEDIAN(K11:T11),"") -> 0.065642147 | E11: =Assumptions!$C$5 -> 0.01244 | F11: =IF($C11="L",Assumptions!$C$8,IF($C11="LM",Assumptions!$C$9,IF($C11="UM",Assumptions!$C$10,Assumptions!$C$11))) -> 0.071689 | G11: =IF(J11<Assumptions!$C$13,"",MIN(MAX(D11,E11),F11)) -> 0.065642147 | H11: =IF(G11="","frozen",IF(ROUND(G11-D11,8)>0,"raised by floor",IF(ROUND(G11-D11,8)<0,"cut by cap","unadjusted"))) -> unadjusted | I11: =IF(OR(G11="",D11=""),"",G11-D11) -> 0 | J11: =COUNT(K11:T11) -> 10 | K11: =IF(OR('GNI per capita'!AJ10="",'GNI per capita'!AK10=""),"",'GNI per capita'!AK10/'GNI per capita'!AJ10-1) -> 0.036426117 | L11: =IF(OR('GNI per capita'!AK10="",'GNI per capita'!AL10=""),"",'GNI per capita'!AL10/'GNI per capita'!AK10-1) -> 0.051724138 | M11: =IF(OR('GNI per capita'!AL10="",'GNI per capita'!AM10=""),"",'GNI per capita'!AM10/'GNI per capita'!AL10-1) -> 0.10088272 | N11: =IF(OR('GNI per capita'!AM10="",'GNI per capita'!AN10=""),"",'GNI per capita'!AN10/'GNI per capita'!AM10-1) -> 0.045246277 | O11: =IF(OR('GNI per capita'!AN10="",'GNI per capita'!AO10=""),"",'GNI per capita'!AO10/'GNI per capita'!AN10-1) -> -0.15287671 | P11: =IF(OR('GNI per capita'!AO10="",'GNI per capita'!AP10=""),"",'GNI per capita'!AP10/'GNI per capita'!AO10-1) -> 0.079560155 | Q11: =IF(OR('GNI per capita'!AP10="",'GNI per capita'!AQ10=""),"",'GNI per capita'!AQ10/'GNI per capita'!AP10-1) -> 0.12222888 | R11: =IF(OR('GNI per capita'!AQ10="",'GNI per capita'!AR10=""),"",'GNI per capita'!AR10/'GNI per capita'!AQ10-1) -> 0.08115323 | ... T11: =IF(OR('GNI per capita'!AS10="",'GNI per capita'!AT10=""),"",'GNI per capita'!AT10/'GNI per capita'!AS10-1) -> 0.12216981 | U11: projected
A12: Argentina | B12: ARG | C12: UM | D12: =IFERROR(MEDIAN(K12:T12),"") -> 0.06235372 | E12: =Assumptions!$C$5 -> 0.01244 | F12: =IF($C12="L",Assumptions!$C$8,IF($C12="LM",Assumptions!$C$9,IF($C12="UM",Assumptions!$C$10,Assumptions!$C$11))) -> 0.090712 | G12: =IF(J12<Assumptions!$C$13,"",MIN(MAX(D12,E12),F12)) -> 0.06235372 | H12: =IF(G12="","frozen",IF(ROUND(G12-D12,8)>0,"raised by floor",IF(ROUND(G12-D12,8)<0,"cut by cap","unadjusted"))) -> unadjusted | I12: =IF(OR(G12="",D12=""),"",G12-D12) -> 0 | J12: =COUNT(K12:T12) -> 10 | K12: =IF(OR('GNI per capita'!AJ11="",'GNI per capita'!AK11=""),"",'GNI per capita'!AK11/'GNI per capita'!AJ11-1) -> -0.0296 | L12: =IF(OR('GNI per capita'!AK11="",'GNI per capita'!AL11=""),"",'GNI per capita'!AL11/'GNI per capita'!AK11-1) -> 0.077493817 | M12: =IF(OR('GNI per capita'!AL11="",'GNI per capita'!AM11=""),"",'GNI per capita'!AM11/'GNI per capita'!AL11-1) -> -0.052027544 | N12: =IF(OR('GNI per capita'!AM11="",'GNI per capita'!AN11=""),"",'GNI per capita'!AN11/'GNI per capita'!AM11-1) -> -0.095238095 | O12: =IF(OR('GNI per capita'!AN11="",'GNI per capita'!AO11=""),"",'GNI per capita'!AO11/'GNI per capita'!AN11-1) -> -0.19357716 | P12: =IF(OR('GNI per capita'!AO11="",'GNI per capita'!AP11=""),"",'GNI per capita'!AP11/'GNI per capita'!AO11-1) -> 0.11393805 | Q12: =IF(OR('GNI per capita'!AP11="",'GNI per capita'!AQ11=""),"",'GNI per capita'!AQ11/'GNI per capita'!AP11-1) -> 0.18073486 | R12: =IF(OR('GNI per capita'!AQ11="",'GNI per capita'!AR11=""),"",'GNI per capita'!AR11/'GNI per capita'!AQ11-1) -> 0.086627418 | ... T12: =IF(OR('GNI per capita'!AS11="",'GNI per capita'!AT11=""),"",'GNI per capita'!AT11/'GNI per capita'!AS11-1) -> 0.08277901 | U12: projected
A13: Armenia | B13: ARM | C13: UM | D13: =IFERROR(MEDIAN(K13:T13),"") -> 0.092319026 | E13: =Assumptions!$C$5 -> 0.01244 | F13: =IF($C13="L",Assumptions!$C$8,IF($C13="LM",Assumptions!$C$9,IF($C13="UM",Assumptions!$C$10,Assumptions!$C$11))) -> 0.090712 | G13: =IF(J13<Assumptions!$C$13,"",MIN(MAX(D13,E13),F13)) -> 0.090712 | H13: =IF(G13="","frozen",IF(ROUND(G13-D13,8)>0,"raised by floor",IF(ROUND(G13-D13,8)<0,"cut by cap","unadjusted"))) -> cut by cap | I13: =IF(OR(G13="",D13=""),"",G13-D13) -> -0.0016070257 | J13: =COUNT(K13:T13) -> 10 | K13: =IF(OR('GNI per capita'!AJ12="",'GNI per capita'!AK12=""),"",'GNI per capita'!AK12/'GNI per capita'!AJ12-1) -> -0.056265985 | L13: =IF(OR('GNI per capita'!AK12="",'GNI per capita'!AL12=""),"",'GNI per capita'!AL12/'GNI per capita'!AK12-1) -> 0.056910569 | M13: =IF(OR('GNI per capita'!AL12="",'GNI per capita'!AM12=""),"",'GNI per capita'!AM12/'GNI per capita'!AL12-1) -> 0.082051282 | N13: =IF(OR('GNI per capita'!AM12="",'GNI per capita'!AN12=""),"",'GNI per capita'!AN12/'GNI per capita'!AM12-1) -> 0.10189573 | O13: =IF(OR('GNI per capita'!AN12="",'GNI per capita'!AO12=""),"",'GNI per capita'!AO12/'GNI per capita'!AN12-1) -> -0.090322581 | P13: =IF(OR('GNI per capita'!AO12="",'GNI per capita'!AP12=""),"",'GNI per capita'!AP12/'GNI per capita'!AO12-1) -> 0.082742317 | Q13: =IF(OR('GNI per capita'!AP12="",'GNI per capita'!AQ12=""),"",'GNI per capita'!AQ12/'GNI per capita'!AP12-1) -> 0.24235808 | R13: =IF(OR('GNI per capita'!AQ12="",'GNI per capita'!AR12=""),"",'GNI per capita'!AR12/'GNI per capita'!AQ12-1) -> 0.20386643 | ... T13: =IF(OR('GNI per capita'!AS12="",'GNI per capita'!AT12=""),"",'GNI per capita'!AT12/'GNI per capita'!AS12-1) -> 0.15492958 | U13: projected - cut from 9.2% to the UM p90 cap of 9.07%
